2024-11-30 20:35:15,476 - INFO - Logging initialized
2024-11-30 20:35:15,477 - INFO - Starting Product Dashboard application
2024-11-30 20:35:15,580 - INFO - Initializing ProductDashboard
2024-11-30 20:35:15,609 - INFO - Fetching products from API - Page 1
2024-11-30 20:35:15,610 - INFO - API Request Details:
2024-11-30 20:35:15,610 - INFO -   Endpoint: http://localhost:5000/api/products
2024-11-30 20:35:15,610 - INFO -   Method: GET
2024-11-30 20:35:15,610 - INFO -   Parameters: {'page': 1, 'limit': 10}
2024-11-30 20:35:19,708 - ERROR - Connection error: HTTPConnectionPool(host='localhost', port=5000): Max retries exceeded with url: /api/products?page=1&limit=10 (Caused by NewConnectionError('<urllib3.connection.HTTPConnection object at 0x00000229E0CDCC50>: Failed to establish a new connection: [WinError 10061] No connection could be made because the target machine actively refused it'))
Traceback (most recent call last):
  File "C:\ProgramData\anaconda3\Lib\site-packages\urllib3\connection.py", line 196, in _new_conn
    sock = connection.create_connection(
           ^^^^^^^^^^^^^^^^^^^^^^^^^^^^^
  File "C:\ProgramData\anaconda3\Lib\site-packages\urllib3\util\connection.py", line 85, in create_connection
    raise err
  File "C:\ProgramData\anaconda3\Lib\site-packages\urllib3\util\connection.py", line 73, in create_connection
    sock.connect(sa)
ConnectionRefusedError: [WinError 10061] No connection could be made because the target machine actively refused it

The above exception was the direct cause of the following exception:

Traceback (most recent call last):
  File "C:\ProgramData\anaconda3\Lib\site-packages\urllib3\connectionpool.py", line 789, in urlopen
    response = self._make_request(
               ^^^^^^^^^^^^^^^^^^^
  File "C:\ProgramData\anaconda3\Lib\site-packages\urllib3\connectionpool.py", line 495, in _make_request
    conn.request(
  File "C:\ProgramData\anaconda3\Lib\site-packages\urllib3\connection.py", line 398, in request
    self.endheaders()
  File "C:\ProgramData\anaconda3\Lib\http\client.py", line 1331, in endheaders
    self._send_output(message_body, encode_chunked=encode_chunked)
  File "C:\ProgramData\anaconda3\Lib\http\client.py", line 1091, in _send_output
    self.send(msg)
  File "C:\ProgramData\anaconda3\Lib\http\client.py", line 1035, in send
    self.connect()
  File "C:\ProgramData\anaconda3\Lib\site-packages\urllib3\connection.py", line 236, in connect
    self.sock = self._new_conn()
                ^^^^^^^^^^^^^^^^
  File "C:\ProgramData\anaconda3\Lib\site-packages\urllib3\connection.py", line 211, in _new_conn
    raise NewConnectionError(
urllib3.exceptions.NewConnectionError: <urllib3.connection.HTTPConnection object at 0x00000229E0CDCC50>: Failed to establish a new connection: [WinError 10061] No connection could be made because the target machine actively refused it

The above exception was the direct cause of the following exception:

Traceback (most recent call last):
  File "C:\Users\nickv\AppData\Roaming\Python\Python312\site-packages\requests\adapters.py", line 486, in send
    resp = conn.urlopen(
           ^^^^^^^^^^^^^
  File "C:\ProgramData\anaconda3\Lib\site-packages\urllib3\connectionpool.py", line 843, in urlopen
    retries = retries.increment(
              ^^^^^^^^^^^^^^^^^^
  File "C:\ProgramData\anaconda3\Lib\site-packages\urllib3\util\retry.py", line 519, in increment
    raise MaxRetryError(_pool, url, reason) from reason  # type: ignore[arg-type]
    ^^^^^^^^^^^^^^^^^^^^^^^^^^^^^^^^^^^^^^^^^^^^^^^^^^^
urllib3.exceptions.MaxRetryError: HTTPConnectionPool(host='localhost', port=5000): Max retries exceeded with url: /api/products?page=1&limit=10 (Caused by NewConnectionError('<urllib3.connection.HTTPConnection object at 0x00000229E0CDCC50>: Failed to establish a new connection: [WinError 10061] No connection could be made because the target machine actively refused it'))

During handling of the above exception, another exception occurred:

Traceback (most recent call last):
  File "c:\Users\nickv\Downloads\tester\ecommerce-store-ecom\backend\scripts\product_dashboard.py", line 563, in fetch_products
    response = requests.get(base_url, params=params)
               ^^^^^^^^^^^^^^^^^^^^^^^^^^^^^^^^^^^^^
  File "C:\Users\nickv\AppData\Roaming\Python\Python312\site-packages\requests\api.py", line 73, in get
    return request("get", url, params=params, **kwargs)
           ^^^^^^^^^^^^^^^^^^^^^^^^^^^^^^^^^^^^^^^^^^^^
  File "C:\Users\nickv\AppData\Roaming\Python\Python312\site-packages\requests\api.py", line 59, in request
    return session.request(method=method, url=url, **kwargs)
           ^^^^^^^^^^^^^^^^^^^^^^^^^^^^^^^^^^^^^^^^^^^^^^^^^
  File "C:\Users\nickv\AppData\Roaming\Python\Python312\site-packages\requests\sessions.py", line 589, in request
    resp = self.send(prep, **send_kwargs)
           ^^^^^^^^^^^^^^^^^^^^^^^^^^^^^^
  File "C:\Users\nickv\AppData\Roaming\Python\Python312\site-packages\requests\sessions.py", line 703, in send
    r = adapter.send(request, **kwargs)
        ^^^^^^^^^^^^^^^^^^^^^^^^^^^^^^^
  File "C:\Users\nickv\AppData\Roaming\Python\Python312\site-packages\requests\adapters.py", line 519, in send
    raise ConnectionError(e, request=request)
requests.exceptions.ConnectionError: HTTPConnectionPool(host='localhost', port=5000): Max retries exceeded with url: /api/products?page=1&limit=10 (Caused by NewConnectionError('<urllib3.connection.HTTPConnection object at 0x00000229E0CDCC50>: Failed to establish a new connection: [WinError 10061] No connection could be made because the target machine actively refused it'))
2024-11-30 20:35:19,753 - ERROR - Request Details:
2024-11-30 20:35:19,753 - ERROR -   URL: http://localhost:5000/api/products
2024-11-30 20:35:19,753 - ERROR -   Parameters: {'page': 1, 'limit': 10}
2024-11-30 20:35:19,753 - INFO - Product fetch operation completed
2024-11-30 20:35:19,753 - INFO - Performing initial data fetch
2024-11-30 20:35:19,754 - INFO - Fetching products from API - Page 1
2024-11-30 20:35:19,754 - INFO - API Request Details:
2024-11-30 20:35:19,754 - INFO -   Endpoint: http://localhost:5000/api/products
2024-11-30 20:35:19,754 - INFO -   Method: GET
2024-11-30 20:35:19,755 - INFO -   Parameters: {'page': 1, 'limit': 10}
2024-11-30 20:35:23,851 - ERROR - Connection error: HTTPConnectionPool(host='localhost', port=5000): Max retries exceeded with url: /api/products?page=1&limit=10 (Caused by NewConnectionError('<urllib3.connection.HTTPConnection object at 0x00000229E0CDE180>: Failed to establish a new connection: [WinError 10061] No connection could be made because the target machine actively refused it'))
Traceback (most recent call last):
  File "C:\ProgramData\anaconda3\Lib\site-packages\urllib3\connection.py", line 196, in _new_conn
    sock = connection.create_connection(
           ^^^^^^^^^^^^^^^^^^^^^^^^^^^^^
  File "C:\ProgramData\anaconda3\Lib\site-packages\urllib3\util\connection.py", line 85, in create_connection
    raise err
  File "C:\ProgramData\anaconda3\Lib\site-packages\urllib3\util\connection.py", line 73, in create_connection
    sock.connect(sa)
ConnectionRefusedError: [WinError 10061] No connection could be made because the target machine actively refused it

The above exception was the direct cause of the following exception:

Traceback (most recent call last):
  File "C:\ProgramData\anaconda3\Lib\site-packages\urllib3\connectionpool.py", line 789, in urlopen
    response = self._make_request(
               ^^^^^^^^^^^^^^^^^^^
  File "C:\ProgramData\anaconda3\Lib\site-packages\urllib3\connectionpool.py", line 495, in _make_request
    conn.request(
  File "C:\ProgramData\anaconda3\Lib\site-packages\urllib3\connection.py", line 398, in request
    self.endheaders()
  File "C:\ProgramData\anaconda3\Lib\http\client.py", line 1331, in endheaders
    self._send_output(message_body, encode_chunked=encode_chunked)
  File "C:\ProgramData\anaconda3\Lib\http\client.py", line 1091, in _send_output
    self.send(msg)
  File "C:\ProgramData\anaconda3\Lib\http\client.py", line 1035, in send
    self.connect()
  File "C:\ProgramData\anaconda3\Lib\site-packages\urllib3\connection.py", line 236, in connect
    self.sock = self._new_conn()
                ^^^^^^^^^^^^^^^^
  File "C:\ProgramData\anaconda3\Lib\site-packages\urllib3\connection.py", line 211, in _new_conn
    raise NewConnectionError(
urllib3.exceptions.NewConnectionError: <urllib3.connection.HTTPConnection object at 0x00000229E0CDE180>: Failed to establish a new connection: [WinError 10061] No connection could be made because the target machine actively refused it

The above exception was the direct cause of the following exception:

Traceback (most recent call last):
  File "C:\Users\nickv\AppData\Roaming\Python\Python312\site-packages\requests\adapters.py", line 486, in send
    resp = conn.urlopen(
           ^^^^^^^^^^^^^
  File "C:\ProgramData\anaconda3\Lib\site-packages\urllib3\connectionpool.py", line 843, in urlopen
    retries = retries.increment(
              ^^^^^^^^^^^^^^^^^^
  File "C:\ProgramData\anaconda3\Lib\site-packages\urllib3\util\retry.py", line 519, in increment
    raise MaxRetryError(_pool, url, reason) from reason  # type: ignore[arg-type]
    ^^^^^^^^^^^^^^^^^^^^^^^^^^^^^^^^^^^^^^^^^^^^^^^^^^^
urllib3.exceptions.MaxRetryError: HTTPConnectionPool(host='localhost', port=5000): Max retries exceeded with url: /api/products?page=1&limit=10 (Caused by NewConnectionError('<urllib3.connection.HTTPConnection object at 0x00000229E0CDE180>: Failed to establish a new connection: [WinError 10061] No connection could be made because the target machine actively refused it'))

During handling of the above exception, another exception occurred:

Traceback (most recent call last):
  File "c:\Users\nickv\Downloads\tester\ecommerce-store-ecom\backend\scripts\product_dashboard.py", line 563, in fetch_products
    response = requests.get(base_url, params=params)
               ^^^^^^^^^^^^^^^^^^^^^^^^^^^^^^^^^^^^^
  File "C:\Users\nickv\AppData\Roaming\Python\Python312\site-packages\requests\api.py", line 73, in get
    return request("get", url, params=params, **kwargs)
           ^^^^^^^^^^^^^^^^^^^^^^^^^^^^^^^^^^^^^^^^^^^^
  File "C:\Users\nickv\AppData\Roaming\Python\Python312\site-packages\requests\api.py", line 59, in request
    return session.request(method=method, url=url, **kwargs)
           ^^^^^^^^^^^^^^^^^^^^^^^^^^^^^^^^^^^^^^^^^^^^^^^^^
  File "C:\Users\nickv\AppData\Roaming\Python\Python312\site-packages\requests\sessions.py", line 589, in request
    resp = self.send(prep, **send_kwargs)
           ^^^^^^^^^^^^^^^^^^^^^^^^^^^^^^
  File "C:\Users\nickv\AppData\Roaming\Python\Python312\site-packages\requests\sessions.py", line 703, in send
    r = adapter.send(request, **kwargs)
        ^^^^^^^^^^^^^^^^^^^^^^^^^^^^^^^
  File "C:\Users\nickv\AppData\Roaming\Python\Python312\site-packages\requests\adapters.py", line 519, in send
    raise ConnectionError(e, request=request)
requests.exceptions.ConnectionError: HTTPConnectionPool(host='localhost', port=5000): Max retries exceeded with url: /api/products?page=1&limit=10 (Caused by NewConnectionError('<urllib3.connection.HTTPConnection object at 0x00000229E0CDE180>: Failed to establish a new connection: [WinError 10061] No connection could be made because the target machine actively refused it'))
2024-11-30 20:35:23,860 - ERROR - Request Details:
2024-11-30 20:35:23,861 - ERROR -   URL: http://localhost:5000/api/products
2024-11-30 20:35:23,861 - ERROR -   Parameters: {'page': 1, 'limit': 10}
2024-11-30 20:35:23,861 - INFO - Product fetch operation completed
2024-11-30 20:35:23,862 - INFO - Application initialized. Log file: logs/product_dashboard_20241130_203515.log
2024-11-30 20:35:23,862 - INFO - Starting main loop
